<?xml version="1.0" ?>
<!-- =================================================================================== -->
<!-- |    This document was autogenerated by xacro from robot.xacro                    | -->
<!-- |    EDITING THIS FILE BY HAND IS NOT RECOMMENDED                                 | -->
<!-- =================================================================================== -->
<robot name="rbq3">
  <material name="black">
    <color rgba="0.0 0.0 0.0 1.0"/>
  </material>
  <material name="blue">
    <color rgba="0.0 0.0 0.8 1.0"/>
  </material>
  <material name="green">
    <color rgba="0.0 0.8 0.0 1.0"/>
  </material>
  <material name="grey">
    <color rgba="0.2 0.2 0.2 1.0"/>
  </material>
  <material name="silver">
    <color rgba="0.913725490196 0.913725490196 0.847058823529 1.0"/>
  </material>
  <material name="orange">
    <color rgba="1.0 0.423529411765 0.0392156862745 1.0"/>
  </material>
  <material name="brown">
    <color rgba="0.870588235294 0.811764705882 0.764705882353 1.0"/>
  </material>
  <material name="red">
    <color rgba="0.8 0.0 0.0 1.0"/>
  </material>
  <material name="white">
    <color rgba="1.0 1.0 1.0 1.0"/>
  </material>

  <!-- ========================== Torso ========================== -->
  <link name="trunk">
    <visual>
	  <origin rpy="0 0 0" xyz="0 0 0"/>
      <geometry>
		<mesh filename="trunk1.dae" scale="1 1 1"/>
      </geometry>
      <material name="orange"/>
    </visual>
    <collision>
      <origin rpy="0 0 0" xyz="0 0 0.0084"/>
      <geometry>
        <box size="0.3 0.15 0.0168"/>
      </geometry>
    </collision>
    <inertial>
      <origin rpy="0 0 0" xyz="-0.34e-03 -0.01e-03 -3.57e-03"/>
      <mass value="11.5756"/>
      <inertia ixx="66750053.32e-09" ixy="-63531.87e-09" ixz="-79250.07e-09" iyy="124905646.11e-09" iyz="-22005.65e-09" izz="177312065.71e-09"/>
    </inertial>
  </link>
  
  <joint name="hip_fixed" type="fixed">
    <origin rpy="0 0 0" xyz="0 0 0"/>
    <parent link="trunk"/>
    <child link="hip_roll_motor"/>
  </joint>
  <link name="hip_roll_motor">
    <visual>
	  <origin rpy="0 0 0" xyz="0 0 0"/>
      <geometry>
		<mesh filename="trunk2.stl" scale="1 1 1"/>
      </geometry>
      <material name="orange"/>
    </visual>
  </link>


  <!-- ========================== Rear Right ========================== -->
  <joint name="RR_hip_joint" type="revolute">
    <origin rpy="0 0 0" xyz="-0.22445 -0.07946 0"/>
    <parent link="trunk"/>
    <child link="RR_hip"/>
    <axis xyz="1 0 0"/>
    <dynamics rotor_inertia="0.00008" damping="0" friction="0"/>
    <limit effort="20" lower="-6.28" upper="6.28" velocity="52.4"/>
  </joint>
  <link name="RR_hip">
    <visual>
      <origin rpy="3.14159265359 3.14159265359 0" xyz="0 0 0"/>
      <geometry>
        <mesh filename="hip.stl" scale="1 1 1"/>
      </geometry>
      <material name="grey"/>
    </visual>
    <collision>
      <origin rpy="1.57079632679 0 0" xyz="0 0.021 0"/>
      <geometry>
        <cylinder length="0.089" radius="0.0445"/>
      </geometry>
    </collision>
    <inertial>
      <origin rpy="0 0 0" xyz="4.51e-03 -17.58e-03 0.04e-03"/>
      <mass value="2.38674"/>
      <inertia ixx="3437636.42e-09" ixy="120456.91e-09" ixz="-569.13e-09" iyy="2718636.62e-09" iyz="-3826.95e-09" izz="3437712.56e-09"/>
    </inertial>
  </link>
  <joint name="RR_thigh_joint" type="revolute">
    <origin rpy="0 0 0" xyz="0 -0.06995 0"/>
    <parent link="RR_hip"/>
    <child link="RR_thigh"/>
    <axis xyz="0 1 0"/>
    <dynamics rotor_inertia="0.000065" damping="0" friction="0"/>
    <limit effort="30" lower="-6.28" upper="6.28" velocity="28.6"/>
	<!--limit effort="55" lower="-1.5708" upper="3.92699081699" velocity="28.6"/-->
  </joint>
  <link name="RR_thigh">
    <visual>
      <origin rpy="0 0 0" xyz="0 0 0"/>
      <geometry>
        <mesh filename="thigh.dae" scale="1 1 1"/>
      </geometry>
      <material name="grey"/>
    </visual>
    <collision>
      <origin rpy="0 1.57079632679 0" xyz="0 0 -0.1125"/>
      <geometry>
        <box size="0.225 0.04 0.04"/>
      </geometry>
    </collision>
    <inertial>
      <origin rpy="0 0 0" xyz="-2.26e-03 -7.68e-03 -41.12e-03"/>
      <mass value="0.67231"/>
      <inertia ixx="3146944.77e-09" ixy="-4356.11e-09" ixz="98512.25e-09" iyy="3429086.75e-09" iyz="-158744.35e-09" izz="636166.40e-09"/>
    </inertial>
  </link>
  <joint name="RR_calf_joint" type="revolute">
    <origin rpy="0 0 0" xyz="0 0 -0.225"/>
    <parent link="RR_thigh"/>
    <child link="RR_calf"/>
    <axis xyz="0 1 0"/>
    <dynamics rotor_inertia="0.00005" damping="0" friction="0"/>
    <limit effort="30" lower="-2.77507351067" upper="-0.610865238198" velocity="28.6"/>
  </joint>
  <link name="RR_calf">
    <visual>
      <origin rpy="0 0 0" xyz="0 0 0"/>
      <geometry>
        <mesh filename="calf.stl" scale="1 1 1"/>
      </geometry>
      <material name="silver"/>
    </visual>
    <collision>
      <origin rpy="0 1.57079632679 0" xyz="0 0 -0.1125"/>
      <geometry>
        <box size="0.225 0.025 0.025"/>
      </geometry>
    </collision>
    <inertial>
      <origin rpy="0 0 0" xyz="0.75e-03 0.35e-03 -88.03e-03"/>
      <mass value="0.173"/>
      <inertia ixx="1256859.90e-09" ixy="13.94e-09" ixz="-1349.76e-09" iyy="1263569.86e-09" iyz="-10047.10e-09" izz="18848.54e-09"/>
    </inertial>
  </link>
  <joint name="RR_foot_fixed" type="fixed">
    <origin rpy="0 0 0" xyz="0 0 -0.225"/>
    <parent link="RR_calf"/>
    <child link="RR_foot"/>
  </joint>
  <link name="RR_foot">
    <visual>
      <origin rpy="0 0 0" xyz="0 0 0"/>
      <geometry>
        <sphere radius="0.025"/>
      </geometry>
	  <material name="grey"/>
    </visual>
    <collision>
      <origin rpy="0 0 0" xyz="0 0 0"/>
      <geometry>
        <sphere radius="0.025"/>
      </geometry>
    </collision>
    <inertial>
      <!--<mass value="0.02003"/>-->
      <mass value="0.0"/>
      <inertia ixx="1930e-09" ixy="0.0" ixz="0.0" iyy="2895e-09" iyz="0.0" izz="1930e-09"/>
    </inertial>
  </link>

  <!-- ========================== Rear Left ========================== -->
  <joint name="RL_hip_joint" type="revolute">
    <origin rpy="0 0 0" xyz="-0.22445 0.07946 0"/>
    <parent link="trunk"/>
    <child link="RL_hip"/>
    <axis xyz="1 0 0"/>
    <dynamics rotor_inertia="0.00008" damping="0" friction="0"/>
    <limit effort="30" lower="-6.28" upper="6.28" velocity="52.4"/>
  </joint>
  <link name="RL_hip">
    <visual>
      <origin rpy="0 3.14159265359 0" xyz="0 0 0"/>
      <geometry>
        <mesh filename="hip.stl" scale="1 1 1"/>
      </geometry>
      <material name="grey"/>
    </visual>
    <collision>
      <origin rpy="1.57079632679 0 0" xyz="0 -0.021 0"/>
      <geometry>
        <cylinder length="0.089" radius="0.0445"/>
      </geometry>
    </collision>
    <inertial>
      <origin rpy="0 0 0" xyz="4.51e-03 17.58e-03 0.04e-03"/>
      <mass value="2.38674"/>
      <inertia ixx="3437636.42e-09" ixy="-120456.91e-09" ixz="-569.13e-09" iyy="2718636.62e-09" iyz="3826.95e-09" izz="3437712.56e-09"/>
    </inertial>
  </link>
  <joint name="RL_thigh_joint" type="revolute">
    <origin rpy="0 0 0" xyz="0 0.06995 0"/>
    <parent link="RL_hip"/>
    <child link="RL_thigh"/>
    <axis xyz="0 1 0"/>
    <dynamics rotor_inertia="0.000065" damping="0" friction="0"/>
    <limit effort="30" lower="-6.28" upper="6.28" velocity="28.6"/>
	<!--limit effort="55" lower="-1.5708" upper="3.92699081699" velocity="28.6"/-->
  </joint>
  <link name="RL_thigh">
    <visual>
      <origin rpy="0 0 0" xyz="0 0 0"/>
      <geometry>
        <mesh filename="thigh.dae" scale="1 1 1"/>
      </geometry>
    </visual>
    <collision>
      <origin rpy="0 1.57079632679 0" xyz="0 0 -0.1125"/>
      <geometry>
        <box size="0.225 0.04 0.04"/>
      </geometry>
    </collision>
    <inertial>
      <origin rpy="0 0 0" xyz="-2.26e-03 7.68e-03 -41.12e-03"/>
      <mass value="0.67231"/>
      <inertia ixx="3146944.77e-09" ixy="4356.11e-09" ixz="98512.25e-09" iyy="3429086.75e-09" iyz="158744.35e-09" izz="636166.40e-09"/>
    </inertial>
  </link>
  <joint name="RL_calf_joint" type="revolute">
    <origin rpy="0 0 0" xyz="0 0 -0.225"/>
    <parent link="RL_thigh"/>
    <child link="RL_calf"/>
    <axis xyz="0 1 0"/>
    <dynamics rotor_inertia="0.00005" damping="0" friction="0"/>
    <limit effort="30" lower="-2.77507351067" upper="-0.610865238198" velocity="28.6"/>
  </joint>
  <link name="RL_calf">
    <visual>
      <origin rpy="0 0 0" xyz="0 0 0"/>
      <geometry>
        <mesh filename="calf.stl" scale="1 1 1"/>
      </geometry>
    </visual>
    <collision>
      <origin rpy="0 1.57079632679 0" xyz="0 0 -0.125"/>
      <geometry>
        <box size="0.225 0.025 0.025"/>
      </geometry>
    </collision>
    <inertial>
      <origin rpy="0 0 0" xyz="0.75e-03 0.35e-03 -88.03e-03"/>
      <mass value="0.173"/>
      <inertia ixx="1256859.90e-09" ixy="13.94e-09" ixz="-1349.76e-09" iyy="1263569.86e-09" iyz="-10047.10e-09" izz="18848.54e-09"/>
    </inertial>
  </link>
  <joint name="RL_foot_fixed" type="fixed">
    <origin rpy="0 0 0" xyz="0 0 -0.225"/>
    <parent link="RL_calf"/>
    <child link="RL_foot"/>
  </joint>
  <link name="RL_foot">
    <visual>
      <origin rpy="0 0 0" xyz="0 0 0"/>
      <geometry>
        <sphere radius="0.025"/>
      </geometry>
	  <material name="grey"/>
    </visual>
    <collision>
      <origin rpy="0 0 0" xyz="0 0 0"/>
      <geometry>
        <sphere radius="0.025"/>
      </geometry>
    </collision>
    <inertial>
      <!--<mass value="0.02003"/>-->
      <mass value="0.0"/>
      <inertia ixx="1930e-09" ixy="0.0" ixz="0.0" iyy="2895e-09" iyz="0.0" izz="1930e-09"/>
    </inertial>
  </link>


  <!-- ========================== Front Right ========================== -->
  <joint name="FR_hip_joint" type="revolute">
    <origin rpy="0 0 0" xyz="0.22445 -0.07946 0"/>
    <parent link="trunk"/>
    <child link="FR_hip"/>
    <axis xyz="1 0 0"/>
    <dynamics rotor_inertia="0.00008" damping="0" friction="0"/>
    <limit effort="30" lower="-6.28" upper="6.28" velocity="52.4"/>
  </joint>
  <link name="FR_hip">
    <visual>
      <origin rpy="3.14159265359 0 0" xyz="0 0 0"/>
      <geometry>
        <mesh filename="hip.stl" scale="1 1 1"/>
      </geometry>
      <material name="grey"/>
    </visual>
    <collision>
      <origin rpy="1.57079632679 0 0" xyz="0 0.021 0"/>
      <geometry>
        <cylinder length="0.089" radius="0.0445"/>
      </geometry>
    </collision>
    <inertial>
      <origin rpy="0 0 0" xyz="-4.51e-03 -17.58e-03 0.04e-03"/>
      <mass value="2.38674"/>
      <inertia ixx="3437636.42e-09" ixy="-120456.91e-09" ixz="569.13e-09" iyy="2718636.62e-09" iyz="-3826.95e-09" izz="3437712.56e-09"/>
    </inertial>
  </link>
  <joint name="FR_thigh_joint" type="revolute">
    <origin rpy="0 0 0" xyz="0 -0.06995 0"/>
    <parent link="FR_hip"/>
    <child link="FR_thigh"/>
    <axis xyz="0 1 0"/>
    <dynamics rotor_inertia="0.000065" damping="0" friction="0"/>
    <limit effort="30" lower="-6.28" upper="6.28" velocity="28.6"/>
	<!--limit effort="55" lower="-1.5708" upper="3.92699081699" velocity="28.6"/-->
  </joint>
  <link name="FR_thigh">
    <visual>
      <origin rpy="0 0 0" xyz="0 0 0"/>
      <geometry>
        <mesh filename="thigh.dae" scale="1 1 1"/>
      </geometry>
      <material name="grey"/>
    </visual>
    <collision>
      <origin rpy="0 1.57079632679 0" xyz="0 0 -0.1125"/>
      <geometry>
        <box size="0.225 0.04 0.04"/>
      </geometry>
    </collision>
    <inertial>
      <origin rpy="0 0 0" xyz="-2.26e-03 -7.68e-03 -41.12e-03"/>
      <mass value="0.67231"/>
      <inertia ixx="3146944.77e-09" ixy="-4356.11e-09" ixz="98512.25e-09" iyy="3429086.75e-09" iyz="-158744.35e-09" izz="636166.40e-09"/>
    </inertial>
  </link>
  <joint name="FR_calf_joint" type="revolute">
    <origin rpy="0 0 0" xyz="0 0 -0.225"/>
    <parent link="FR_thigh"/>
    <child link="FR_calf"/>
    <axis xyz="0 1 0"/>
    <dynamics rotor_inertia="0.00005" damping="0" friction="0"/>
    <limit effort="30" lower="-2.77507351067" upper="-0.610865238198" velocity="28.6"/>
  </joint>
  <link name="FR_calf">
    <visual>
      <origin rpy="0 0 0" xyz="0 0 0"/>
      <geometry>
        <mesh filename="calf.stl" scale="1 1 1"/>
      </geometry>
      <material name="silver"/>
    </visual>
    <collision>
      <origin rpy="0 1.57079632679 0" xyz="0 0 -0.1125"/>
      <geometry>
        <box size="0.225 0.025 0.025"/>
      </geometry>
    </collision>
    <inertial>
      <origin rpy="0 0 0" xyz="0.75e-03 0.35e-03 -88.03e-03"/>
      <mass value="0.173"/>
      <inertia ixx="1256859.90e-09" ixy="13.94e-09" ixz="-1349.76e-09" iyy="1263569.86e-09" iyz="-10047.10e-09" izz="18848.54e-09"/>
    </inertial>
  </link>
  <joint name="FR_foot_fixed" type="fixed">
    <origin rpy="0 0 0" xyz="0 0 -0.225"/>
    <parent link="FR_calf"/>
    <child link="FR_foot"/>
  </joint>
  <link name="FR_foot">
    <visual>
      <origin rpy="0 0 0" xyz="0 0 0"/>
      <geometry>
        <sphere radius="0.025"/>
      </geometry>
	  <material name="grey"/>
    </visual>
    <collision>
      <origin rpy="0 0 0" xyz="0 0 0"/>
      <geometry>
        <sphere radius="0.025"/>
      </geometry>
    </collision>
    <inertial>
      <!--<mass value="0.02003"/>-->
      <mass value="0.0"/>
      <inertia ixx="1930e-09" ixy="0.0" ixz="0.0" iyy="2895e-09" iyz="0.0" izz="1930e-09"/>
    </inertial>
  </link>

  <!-- ========================== Front Left ========================== -->
  <joint name="FL_hip_joint" type="revolute">
    <origin rpy="0 0 0" xyz="0.22445 0.07946 0"/>
    <parent link="trunk"/>
    <child link="FL_hip"/>
    <axis xyz="1 0 0"/>
    <dynamics rotor_inertia="0.00008" damping="0" friction="0"/>
    <limit effort="30" lower="-6.28" upper="6.28" velocity="52.4"/>
  </joint>
  <link name="FL_hip">
    <visual>
      <origin rpy="0 0 0" xyz="0 0 0"/>
      <geometry>
        <mesh filename="hip.stl" scale="1 1 1"/>
      </geometry>
      <material name="grey"/>
    </visual>
    <collision>
      <origin rpy="1.57079632679 0 0" xyz="0 -0.021 0"/>
      <geometry>
        <cylinder length="0.089" radius="0.0445"/>
      </geometry>
    </collision>
    <inertial>
      <origin rpy="0 0 0" xyz="-4.51e-03 17.58e-03 0.04e-03"/>
      <mass value="2.38674"/>
      <inertia ixx="3437636.42e-09" ixy="120456.91e-09" ixz="569.13e-09" iyy="2718636.62e-09" iyz="3826.95e-09" izz="3437712.56e-09"/>
    </inertial>
  </link>
  <joint name="FL_thigh_joint" type="revolute">
    <origin rpy="0 0 0" xyz="0 0.06995 0"/>
    <parent link="FL_hip"/>
    <child link="FL_thigh"/>
    <axis xyz="0 1 0"/>
    <dynamics rotor_inertia="0.000065" damping="0" friction="0"/>
    <limit effort="30" lower="-6.28" upper="6.28" velocity="28.6"/>
  </joint>
  <link name="FL_thigh">
    <visual>
      <origin rpy="0 0 0" xyz="0 0 0"/>
      <geometry>
        <mesh filename="thigh.dae" scale="1 1 1"/>
      </geometry>
      <material name="grey"/>
    </visual>
    <collision>
      <origin rpy="0 1.57079632679 0" xyz="0 0 -0.1125"/>
      <geometry>
        <box size="0.225 0.04 0.04"/>
      </geometry>
    </collision>
    <inertial>
      <origin rpy="0 0 0" xyz="-2.26e-03 7.68e-03 -41.12e-03"/>
      <mass value="0.67231"/>
      <inertia ixx="3146944.77e-09" ixy="4356.11e-09" ixz="98512.25e-09" iyy="3429086.75e-09" iyz="158744.35e-09" izz="636166.40e-09"/>
    </inertial>
  </link>
  <joint name="FL_calf_joint" type="revolute">
    <origin rpy="0 0 0" xyz="0 0 -0.225"/>
    <parent link="FL_thigh"/>
    <child link="FL_calf"/>
    <axis xyz="0 1 0"/>
    <dynamics rotor_inertia="0.00005" damping="0" friction="0"/>
    <limit effort="30" lower="-2.77507351067" upper="-0.610865238198" velocity="28.6"/>
  </joint>
  <link name="FL_calf">
    <visual>
      <origin rpy="0 0 0" xyz="0 0 0"/>
      <geometry>
        <mesh filename="calf.stl" scale="1 1 1"/>
      </geometry>
      <material name="silver"/>
    </visual>
    <collision>
      <origin rpy="0 1.57079632679 0" xyz="0 0 -0.1125"/>
      <geometry>
        <box size="0.225 0.025 0.025"/>
      </geometry>
    </collision>
    <inertial>
      <origin rpy="0 0 0" xyz="0.75e-03 0.35e-03 -88.03e-03"/>
      <mass value="0.173"/>
      <inertia ixx="1256859.90e-09" ixy="13.94e-09" ixz="-1349.76e-09" iyy="1263569.86e-09" iyz="-10047.10e-09" izz="18848.54e-09"/>
    </inertial>
  </link>
  <joint name="FL_foot_fixed" type="fixed">
    <origin rpy="0 0 0" xyz="0 0 -0.225"/>
    <parent link="FL_calf"/>
    <child link="FL_foot"/>
  </joint>
  <link name="FL_foot">
    <visual>
      <origin rpy="0 0 0" xyz="0 0 0"/>
      <geometry>
        <sphere radius="0.025"/>
      </geometry>
	  <material name="grey"/>
    </visual>
    <collision>
      <origin rpy="0 0 0" xyz="0 0 0"/>
      <geometry>
        <sphere radius="0.025"/>
      </geometry>
    </collision>
    <inertial>
      <!--<mass value="0.02003"/>-->
      <mass value="0.0"/>
      <inertia ixx="1930e-09" ixy="0.0" ixz="0.0" iyy="2895e-09" iyz="0.0" izz="1930e-09"/>
    </inertial>
  </link>
</robot>
