<?xml version="1.0"?>
<sdf version='1.7'>
  <model name='ST_Arm'>

    <joint name='world_joint' type='fixed'>
      <child>base_link</child>
      <parent>world</parent>
      <axis>
        <xyz>0 0 0</xyz>
        <limit>
          <lower>-1e+16</lower>
          <upper>1e+16</upper>
        </limit>
        <dynamics>
          <spring_reference>0</spring_reference>
          <spring_stiffness>0</spring_stiffness>
        </dynamics>
        <use_parent_model_frame>1</use_parent_model_frame>
      </axis>      
    </joint>


    <link name='base_link'>
      <inertial>
        <pose>-0.000106 -0.000106 0.023113 0 -0 0</pose>
        <mass>0.76531</mass>
        <inertia>
          <ixx>0.0010366</ixx>
          <ixy>-5.1407e-06</ixy>
          <ixz>5.5618e-06</ixz>
          <iyy>0.00076329</iyy>
          <iyz>-6.6485e-07</iyz>
          <izz>0.0016444</izz>
        </inertia>
      </inertial>
      <collision name='base_link_collision'>
        <pose>0 0 0 0 -0 0</pose>
        <geometry>
          <mesh>
            <scale>1 1 1</scale>
            <uri>model://st_arm_description/meshes/base_link.STL</uri>
          </mesh>
        </geometry>
      </collision>
      <visual name='base_link_visual'>
        <pose>0 0 0 0 -0 0</pose>
        <geometry>
          <mesh>
            <scale>1 1 1</scale>
            <uri>model://st_arm_description/meshes/collada/base_link.dae</uri>
          </mesh>
        </geometry>
      </visual>
      
      
      <sensor name="IMX219_Front" type="camera">
        <pose>+0.12 +0 +0 0 0 0</pose>
        <camera>
          <horizontal_fov>1.747</horizontal_fov>
          <image>
            <format>R8G8B8</format>
            <width>848</width>
            <height>480</height>
          </image>
          <clip>
            <near>0.02</near>
            <far>100</far>
          </clip>
        </camera>
        <plugin name="camera_controller" filename="libgazebo_ros_camera.so">
          <alwaysOn>true</alwaysOn>
          <updateRate>60</updateRate>
          <cameraName>Front</cameraName>
          <imageTopicName>image_raw</imageTopicName>
          <cameraInfoTopicName>camera_info</cameraInfoTopicName>
          <frameName>camera_link</frameName>
        </plugin>
        <visualize>true</visualize>
      </sensor>
      <sensor name="IMX219_Back" type="camera">
        <pose>-0.12 +0 +0 0 0 3.141592</pose>
        <camera>
          <horizontal_fov>1.747</horizontal_fov>
          <image>
            <format>R8G8B8</format>
            <width>848</width>
            <height>480</height>
          </image>
          <clip>
            <near>0.02</near>
            <far>100</far>
          </clip>
        </camera>
        <plugin name="camera_controller" filename="libgazebo_ros_camera.so">
          <alwaysOn>true</alwaysOn>
          <updateRate>60</updateRate>
          <cameraName>Back</cameraName>
          <imageTopicName>image_raw</imageTopicName>
          <cameraInfoTopicName>camera_info</cameraInfoTopicName>
          <frameName>camera_link</frameName>
        </plugin>
        <visualize>true</visualize>
      </sensor>
      <sensor name="IMX219_Left" type="camera">
        <pose>+0 +0.1 +0 0 0 1.570796</pose>
        <camera>
          <horizontal_fov>1.747</horizontal_fov>
          <image>
            <format>R8G8B8</format>
            <width>848</width>
            <height>480</height>
          </image>
          <clip>
            <near>0.02</near>
            <far>100</far>
          </clip>
        </camera>
        <plugin name="camera_controller" filename="libgazebo_ros_camera.so">
          <alwaysOn>true</alwaysOn>
          <updateRate>60</updateRate>
          <cameraName>Left</cameraName>
          <imageTopicName>image_raw</imageTopicName>
          <cameraInfoTopicName>camera_info</cameraInfoTopicName>
          <frameName>camera_link</frameName>
        </plugin>
        <visualize>true</visualize>
      </sensor>
      <sensor name="IMX219_Right" type="camera">
        <pose>+0 -0.1 +0 0 0 4.712388</pose>
        <camera>
          <horizontal_fov>1.747</horizontal_fov>
          <image>
            <format>R8G8B8</format>
            <width>848</width>
            <height>480</height>
          </image>
          <clip>
            <near>0.02</near>
            <far>100</far>
          </clip>
        </camera>
        <plugin name="camera_controller" filename="libgazebo_ros_camera.so">
          <alwaysOn>true</alwaysOn>
          <updateRate>60</updateRate>
          <cameraName>Right</cameraName>
          <imageTopicName>image_raw</imageTopicName>
          <cameraInfoTopicName>camera_info</cameraInfoTopicName>
          <frameName>camera_link</frameName>
        </plugin>
        <visualize>true</visualize>
      </sensor>
      
     
    </link>
    <joint name='shoulder_yaw_joint' type='revolute'>
      <pose relative_to='base_link'>0 0 0 0 -0 0</pose>
      <parent>base_link</parent>
      <child>shoulder_yaw_link</child>
      <axis>
        <xyz>0 0 1</xyz>
        <limit>
          <lower>-3.14</lower>
          <upper>3.14</upper>
          <effort>1</effort>
          <velocity>1</velocity>
        </limit>
        <dynamics>
          <damping>0.1</damping>
          <friction>0.1</friction>
          <spring_reference>0</spring_reference>
          <spring_stiffness>0</spring_stiffness>
        </dynamics>
      </axis>
    </joint>
    <link name='shoulder_yaw_link'>
      <pose relative_to='shoulder_yaw_joint'>0 0 0 0 -0 0</pose>
      <inertial>
        <pose>-0.00063 0.025208 0.10003 0 -0 0</pose>
        <mass>0.55193</mass>
        <inertia>
          <ixx>0.00033449</ixx>
          <ixy>-4.0545e-06</ixy>
          <ixz>-1.1656e-06</ixz>
          <iyy>0.00041113</iyy>
          <iyz>3.6907e-07</iyz>
          <izz>0.00034636</izz>
        </inertia>
      </inertial>
      <collision name='shoulder_yaw_link_collision'>
        <pose>0 0 0 0 -0 0</pose>
        <geometry>
          <mesh>
            <scale>1 1 1</scale>
            <uri>model://st_arm_description/meshes/shoulder_yaw_link.STL</uri>
          </mesh>
        </geometry>
      </collision>
      <visual name='shoulder_yaw_link_visual'>
        <pose>0 0 0 0 -0 0</pose>
        <geometry>
          <mesh>
            <scale>1 1 1</scale>
            <uri>model://st_arm_description/meshes/collada/shoulder_yaw_link.dae</uri>
          </mesh>
        </geometry>
      </visual>
    </link>
    <joint name='sholder_pitch_joint' type='revolute'>
      <pose relative_to='shoulder_yaw_link'>0 0 0.1065 0 -0 0</pose>
      <parent>shoulder_yaw_link</parent>
      <child>shoulder_pitch_link</child>
      <axis>
        <xyz>0 1 0</xyz>
        <limit>
          <lower>-3.14</lower>
          <upper>0.1</upper>
          <effort>1</effort>
          <velocity>1</velocity>
        </limit>
        <dynamics>
          <damping>0.1</damping>
          <friction>0.1</friction>
          <spring_reference>0</spring_reference>
          <spring_stiffness>0</spring_stiffness>
        </dynamics>
      </axis>
    </joint>
    <link name='shoulder_pitch_link'>
      <pose relative_to='sholder_pitch_joint'>0 0 0 0 -0 0</pose>
      <inertial>
        <pose>0.02855 -0.023437 9e-06 0 -0 0</pose>
        <mass>0.65914</mass>
        <inertia>
          <ixx>0.00029567</ixx>
          <ixy>2.8845e-06</ixy>
          <ixz>4.3699e-07</ixz>
          <iyy>0.001488</iyy>
          <iyz>3.3829e-08</iyz>
          <izz>0.0013364</izz>
        </inertia>
      </inertial>
      <collision name='shoulder_pitch_link_collision'>
        <pose>0 0 0 0 -0 0</pose>
        <geometry>
          <mesh>
            <scale>1 1 1</scale>
            <uri>model://st_arm_description/meshes/shoulder_pitch.STL</uri>
          </mesh>
        </geometry>
      </collision>
      <visual name='shoulder_pitch_link_visual'>
        <pose>0 0 0 0 -0 0</pose>
        <geometry>
          <mesh>
            <scale>1 1 1</scale>
            <uri>model://st_arm_description/meshes/collada/shoulder_pitch_link.dae</uri>
          </mesh>
        </geometry>
      </visual>
    </link>
    <joint name='elbow_pitch_joint' type='revolute'>
      <pose relative_to='shoulder_pitch_link'>0.2495 0 0 0 -0 0</pose>
      <parent>shoulder_pitch_link</parent>
      <child>elbow_pitch_link</child>
      <axis>
        <xyz>0 1 0</xyz>
        <limit>
          <effort>1</effort>
          <velocity>1</velocity>
          <lower>-1e+16</lower>
          <upper>1e+16</upper>
        </limit>
        <dynamics>
          <damping>0.1</damping>
          <friction>0.1</friction>
          <spring_reference>0</spring_reference>
          <spring_stiffness>0</spring_stiffness>
        </dynamics>
      </axis>
    </joint>
    <link name='elbow_pitch_link'>
      <pose relative_to='elbow_pitch_joint'>0 0 0 0 -0 0</pose>
      <inertial>
        <pose>0.12662 7.7e-05 0.019568 0 -0 0</pose>
        <mass>0.2214</mass>
        <inertia>
          <ixx>7.9835e-05</ixx>
          <ixy>9.3938e-10</ixy>
          <ixz>-3.6943e-06</ixz>
          <iyy>0.00071172</iyy>
          <iyz>-5.0748e-10</iyz>
          <izz>0.00066982</izz>
        </inertia>
      </inertial>
      <collision name='elbow_pitch_link_collision'>
        <pose>0 0 0 0 -0 0</pose>
        <geometry>
          <mesh>
            <scale>1 1 1</scale>
            <uri>model://st_arm_description/meshes/elbow_pitch.STL</uri>
          </mesh>
        </geometry>
      </collision>
      <visual name='elbow_pitch_link_visual'>
        <pose>0 0 0 0 -0 0</pose>
        <geometry>
          <mesh>
            <scale>1 1 1</scale>
            <uri>model://st_arm_description/meshes/collada/elbow_pitch_link.dae</uri>
          </mesh>
        </geometry>
      </visual>
    </link>
    <joint name='wrist_pitch_joint' type='revolute'>
      <pose relative_to='elbow_pitch_link'>0.25 0 0 0 -0 0</pose>
      <parent>elbow_pitch_link</parent>
      <child>wrist_pitch_link</child>
      <axis>
        <xyz>0 1 0</xyz>
        <limit>
          <effort>1</effort>
          <velocity>1</velocity>
          <lower>-1e+16</lower>
          <upper>1e+16</upper>
        </limit>
        <dynamics>
          <damping>0.1</damping>
          <friction>0.1</friction>
          <spring_reference>0</spring_reference>
          <spring_stiffness>0</spring_stiffness>
        </dynamics>
      </axis>
    </joint>
    <link name='wrist_pitch_link'>
      <pose relative_to='wrist_pitch_joint'>0 0 0 0 -0 0</pose>
      <inertial>
        <pose>0.045182 0 0.011395 0 -0 0</pose>
        <mass>0.049194</mass>
        <inertia>
          <ixx>1.2371e-05</ixx>
          <ixy>-4.5811e-15</ixy>
          <ixz>-1.6191e-07</ixz>
          <iyy>1.3055e-05</iyy>
          <iyz>2.315e-14</iyz>
          <izz>8.4091e-06</izz>
        </inertia>
      </inertial>
      <collision name='wrist_pitch_link_collision'>
        <pose>0 0 0 0 -0 0</pose>
        <geometry>
          <mesh>
            <scale>1 1 1</scale>
            <uri>model://st_arm_description/meshes/wrist_pitch_link.STL</uri>
          </mesh>
        </geometry>
      </collision>
      <visual name='wrist_pitch_link_visual'>
        <pose>0 0 0 0 -0 0</pose>
        <geometry>
          <mesh>
            <scale>1 1 1</scale>
            <uri>model://st_arm_description/meshes/collada/wrist_pitch_link.dae</uri>
          </mesh>
        </geometry>
      </visual>
    </link>
    <joint name='wrist_roll_joint' type='revolute'>
      <pose relative_to='wrist_pitch_link'>0 0 0 0 -0 0</pose>
      <parent>wrist_pitch_link</parent>
      <child>wrist_roll_link</child>
      <axis>
        <xyz>1 0 0</xyz>
        <limit>
          <effort>1</effort>
          <velocity>1</velocity>
          <lower>-1e+16</lower>
          <upper>1e+16</upper>
        </limit>
        <dynamics>
          <damping>0.1</damping>
          <friction>0.1</friction>
          <spring_reference>0</spring_reference>
          <spring_stiffness>0</spring_stiffness>
        </dynamics>
      </axis>
    </joint>
    <link name='wrist_roll_link'>
      <pose relative_to='wrist_roll_joint'>0 0 0 0 -0 0</pose>
      <inertial>
        <pose>0.093721 0 0.000367 0 -0 0</pose>
        <mass>0.046957</mass>
        <inertia>
          <ixx>7.5955e-06</ixx>
          <ixy>-1.0153e-14</ixy>
          <ixz>1.6017e-09</ixz>
          <iyy>1.2458e-05</iyy>
          <iyz>-5.0226e-15</iyz>
          <izz>1.072e-05</izz>
        </inertia>
      </inertial>
      <collision name='wrist_roll_link_collision'>
        <pose>0 0 0 0 -0 0</pose>
        <geometry>
          <mesh>
            <scale>1 1 1</scale>
            <uri>model://st_arm_description/meshes/wrist_roll_link.STL</uri>
          </mesh>
        </geometry>
      </collision>
      <visual name='wrist_roll_link_visual'>
        <pose>0 0 0 0 -0 0</pose>
        <geometry>
          <mesh>
            <scale>1 1 1</scale>
            <uri>model://st_arm_description/meshes/collada/wrist_roll_link.dae</uri>
          </mesh>
        </geometry>
      </visual>
    </link>
    <joint name='wrist_yaw_joint' type='revolute'>
      <pose relative_to='wrist_roll_link'>0.1065 0 0 0 -0 0</pose>
      <parent>wrist_roll_link</parent>
      <child>wrist_yaw_link</child>
      <axis>
        <xyz>0 0 1</xyz>
        <limit>
          <effort>1</effort>
          <velocity>1</velocity>
          <lower>-1e+16</lower>
          <upper>1e+16</upper>
        </limit>
        <dynamics>
          <damping>0.1</damping>
          <friction>0.1</friction>
          <spring_reference>0</spring_reference>
          <spring_stiffness>0</spring_stiffness>
        </dynamics>
      </axis>
    </joint>
    <link name='wrist_yaw_link'>
      <pose relative_to='wrist_yaw_joint'>0 0 0 0 -0 0</pose>
      <inertial>
        <pose>0.055252 0.000854 0.031929 0 -0 0</pose>
        <mass>0.074873</mass>
        <inertia>
          <ixx>6.1363e-05</ixx>
          <ixy>4.572e-08</ixy>
          <ixz>8.0007e-07</ixz>
          <iyy>1.3781e-05</iyy>
          <iyz>-7.6618e-09</iyz>
          <izz>5.3819e-05</izz>
        </inertia>
      </inertial>
      <collision name='wrist_yaw_link_collision'>
        <pose>0 0 0 0 -0 0</pose>
        <geometry>
          <mesh>
            <scale>1 1 1</scale>
            <uri>model://st_arm_description/meshes/wrist_yaw_link.STL</uri>
          </mesh>
        </geometry>
      </collision>
      <visual name='wrist_yaw_link_visual'>
        <pose>0 0 0 0 -0 0</pose>
        <geometry>
          <mesh>
            <scale>1 1 1</scale>
            <uri>model://st_arm_description/meshes/collada/wrist_yaw_link.dae</uri>
          </mesh>
        </geometry>
      </visual>
      
      
      <sensor name="D435" type="depth">
        <pose>+0.07 +0 +0.05 0 0 0</pose>
        <camera>
          <horizontal_fov>1.747</horizontal_fov>
          <image>
            <format>B8G8R8</format>
            <width>848</width>
            <height>480</height>
          </image>
          <clip>
            <near>0.02</near>
            <far>100</far>
          </clip>
        </camera>
        
        <plugin name="camera_plugin" filename="libgazebo_ros_openni_kinect.so">
          <baseline>0.2</baseline>
          <alwaysOn>true</alwaysOn>
          <updateRate>0.0</updateRate>
          <cameraName>camera_ir</cameraName>
          <imageTopicName>/D435_RGB/image_raw</imageTopicName>
          <cameraInfoTopicName>/camera/color/camera_info</cameraInfoTopicName>
          <depthImageTopicName>/D435_Depth/image_raw</depthImageTopicName>
          <depthImageCameraInfoTopicName>/camera/depth/camera_info</depthImageCameraInfoTopicName>
          <pointCloudTopicName>/camera/depth/points</pointCloudTopicName>
          <frameName>camera_link</frameName>
          <pointCloudCutoff>0.2</pointCloudCutoff>
          <pointCloudCutoffMax>8.0</pointCloudCutoffMax>
          <min_depth>0.2</min_depth>
          <max_depth>8.0</max_depth>
          <distortionK1>0</distortionK1>
          <distortionK2>0</distortionK2>
          <distortionK3>0</distortionK3>
          <distortionT1>0</distortionT1>
          <distortionT2>0</distortionT2>
          <CxPrime>0</CxPrime>
          <Cx>0</Cx>
          <Cy>0</Cy>
          <focalLength>0</focalLength>
          <hackBaseline>0</hackBaseline>
        </plugin>
        
        <!--
        <plugin name="camera_controller" filename="libgazebo_ros_camera.so">
          <alwaysOn>true</alwaysOn>
          <updateRate>60</updateRate>
          <cameraName>D435_depth</cameraName>
          <imageTopicName>image_raw</imageTopicName>
          <cameraInfoTopicName>camera_info</cameraInfoTopicName>
          <frameName>camera_link_optical</frameName>
        </plugin>
        -->
        <visualize>true</visualize>
      </sensor>
      
      
    </link>
    <joint name='gripper_left_joint' type='prismatic'>
      <pose relative_to='wrist_yaw_link'>0.066959 0.014903 0 0 -0 0</pose>
      <parent>wrist_yaw_link</parent>
      <child>gripper_left_link</child>
      <axis>
        <xyz>0 -1 0</xyz>
        <limit>
          <lower>-0.045</lower>
          <upper>0</upper>
          <effort>1</effort>
          <velocity>1</velocity>
        </limit>
        <dynamics>
          <damping>0.1</damping>
          <friction>0.1</friction>
          <spring_reference>0</spring_reference>
          <spring_stiffness>0</spring_stiffness>
        </dynamics>
      </axis>
    </joint>
    <link name='gripper_left_link'>
      <pose relative_to='gripper_left_joint'>0 0 0 0 -0 0</pose>
      <inertial>
        <pose>0.022803 0.003833 -0 0 -0 0</pose>
        <mass>0.015354</mass>
        <inertia>
          <ixx>1.6124e-06</ixx>
          <ixy>1.0037e-06</ixy>
          <ixz>1.5312e-21</ixz>
          <iyy>6.0714e-06</iyy>
          <iyz>2.6294e-23</iyz>
          <izz>7.1475e-06</izz>
        </inertia>
      </inertial>
      <collision name='gripper_left_link_collision'>
        <pose>0 0 0 0 -0 0</pose>
        <geometry>
          <mesh>
            <scale>1 1 1</scale>
            <uri>model://st_arm_description/meshes/gripper_left_link.STL</uri>
          </mesh>
        </geometry>
      </collision>
      <visual name='gripper_left_link_visual'>
        <pose>0 0 0 0 -0 0</pose>
        <geometry>
          <mesh>
            <scale>1 1 1</scale>
            <uri>model://st_arm_description/meshes/collada/gripper_left_link.dae</uri>
          </mesh>
        </geometry>
      </visual>
    </link>
    <joint name='gripper_right_joint' type='prismatic'>
      <pose relative_to='wrist_yaw_link'>0.066959 -0.014903 0 0 -0 0</pose>
      <parent>wrist_yaw_link</parent>
      <child>gripper_right_link</child>
      <axis>
        <xyz>0 -1 0</xyz>
        <limit>
          <lower>0</lower>
          <upper>0.045</upper>
          <effort>1</effort>
          <velocity>1</velocity>
        </limit>
        <dynamics>
          <damping>0.1</damping>
          <friction>0.1</friction>
          <spring_reference>0</spring_reference>
          <spring_stiffness>0</spring_stiffness>
        </dynamics>
      </axis>
    </joint>
    <link name='gripper_right_link'>
      <pose relative_to='gripper_right_joint'>0 0 0 0 -0 0</pose>
      <inertial>
        <pose>0.022803 -0.003833 0 0 -0 0</pose>
        <mass>0.015354</mass>
        <inertia>
          <ixx>1.6124e-06</ixx>
          <ixy>-1.0037e-06</ixy>
          <ixz>1.1295e-21</ixz>
          <iyy>6.0714e-06</iyy>
          <iyz>3.0821e-22</iyz>
          <izz>7.1475e-06</izz>
        </inertia>
      </inertial>
      <collision name='gripper_right_link_collision'>
        <pose>0 0 0 0 -0 0</pose>
        <geometry>
          <mesh>
            <scale>1 1 1</scale>
            <uri>model://st_arm_description/meshes/gripper_right_link.STL</uri>
          </mesh>
        </geometry>
      </collision>
      <visual name='gripper_right_link_visual'>
        <pose>0 0 0 0 -0 0</pose>
        <geometry>
          <mesh>
            <scale>1 1 1</scale>
            <uri>model://st_arm_description/meshes/collada/gripper_right_link.dae</uri>
          </mesh>
        </geometry>
      </visual>
    </link>
  </model>
</sdf>
