<?xml version="1.0" encoding="utf-8"?>
<sdf version='1.7'>
  <model name='st_arm'>

    <joint name='world_joint' type='fixed'>
      <child>base_link</child>
      <parent>world</parent>
      <axis>
        <xyz>0 0 0</xyz>
        <limit>
          <lower>-1e+16</lower>
          <upper>1e+16</upper>
        </limit>
        <dynamics>
          <spring_reference>0</spring_reference>
          <spring_stiffness>0</spring_stiffness>
        </dynamics>
        <use_parent_model_frame>1</use_parent_model_frame>
      </axis>      
    </joint>
    <link name='base_link'>
      <!--
      <inertial>
        <pose>0.000796 -3.6e-05 0.035389 0 -0 0</pose>
        <mass>0.068254</mass>
        <inertia>
          <ixx>3.8257e-05</ixx>
          <ixy>-1.4789e-08</ixy>
          <ixz>-5.913e-07</ixz>
          <iyy>3.6476e-05</iyy>
          <iyz>-3.6277e-09</iyz>
          <izz>5.5945e-05</izz>
        </inertia>
      </inertial>
      <collision name='base_link_collision'>
        <pose>0 0 0 0 -0 0</pose>
        <geometry>
          <mesh>
            <scale>1 1 1</scale>
            <uri>model://st_arm_description/meshes/stl/base_link.STL</uri>
          </mesh>
        </geometry>
      </collision>
      -->
      <visual name='base_link_visual'>
        <pose>0 0 0 0 -0 0</pose>
        <geometry>
          <mesh>
            <scale>1 1 1</scale>
            <uri>model://st_arm_description/meshes/stl/base_link.STL</uri>
          </mesh>
        </geometry>
      </visual>
    </link>
    <joint name='shoulder_yaw_joint' type='revolute'>
      <pose relative_to='base_link'>0 0 0 0 -0 0</pose>
      <parent>base_link</parent>
      <child>shoulder_yaw_link</child>
      <axis>
        <xyz>0 0 1</xyz>
        <limit>
          <lower>-3.14</lower>
          <upper>3.14</upper>
          <effort>1</effort>
          <velocity>1</velocity>
        </limit>
        <dynamics>
          <damping>0.1</damping>
          <friction>0.1</friction>
          <spring_reference>0</spring_reference>
          <spring_stiffness>0</spring_stiffness>
        </dynamics>
      </axis>
    </joint>
    <link name='shoulder_yaw_link'>
      <pose relative_to='shoulder_yaw_joint'>0 0 0 0 -0 0</pose>
      <inertial>
        <pose>-0.000383 -0.007781 0.091573 0 -0 0</pose>
        <mass>0.11951</mass>
        <inertia>
          <ixx>4.8912e-05</ixx>
          <ixy>5.139e-07</ixy>
          <ixz>7.7875e-07</ixz>
          <iyy>8.0458e-05</iyy>
          <iyz>3.5883e-08</iyz>
          <izz>6.5405e-05</izz>
        </inertia>
      </inertial>
      <!--
      <collision name='shoulder_yaw_link_collision'>
        <pose>0 0 0 0 -0 0</pose>
        <geometry>
          <mesh>
            <scale>1 1 1</scale>
            <uri>model://st_arm_description/meshes/stl/shoulder_yaw_link.STL</uri>
          </mesh>
        </geometry>
      </collision>
      -->
      <visual name='shoulder_yaw_link_visual'>
        <pose>0 0 0 0 -0 0</pose>
        <geometry>
          <mesh>
            <scale>1 1 1</scale>
            <uri>model://st_arm_description/meshes/stl/shoulder_yaw_link.STL</uri>
          </mesh>
        </geometry>
      </visual>
    </link>
    <joint name='shoulder_pitch_joint' type='revolute'>
      <pose relative_to='shoulder_yaw_link'>0 0 0.1024 0 -0 0</pose>
      <parent>shoulder_yaw_link</parent>
      <child>shoulder_pitch_link</child>
      <axis>
        <xyz>0 1 0</xyz>
        <limit>
          <lower>-3.14</lower>
          <upper>0.1</upper>
          <effort>1</effort>
          <velocity>1</velocity>
        </limit>
        <dynamics>
          <damping>0.1</damping>
          <friction>0.1</friction>
          <spring_reference>0</spring_reference>
          <spring_stiffness>0</spring_stiffness>
        </dynamics>
      </axis>
    </joint>
    <link name='shoulder_pitch_link'>
      <pose relative_to='shoulder_pitch_joint'>0 0 0 0 -0 0</pose>
      <inertial>
        <pose>0.15644 0.048066 1e-05 0 -0 0</pose>
        <mass>0.24697</mass>
        <inertia>
          <ixx>9.437e-05</ixx>
          <ixy>3.5353e-07</ixy>
          <ixz>-1.4925e-08</ixz>
          <iyy>0.00039967</iyy>
          <iyz>-3.7482e-09</iyz>
          <izz>0.0003625</izz>
        </inertia>
      </inertial>
      <!--
      <collision name='shoulder_pitch_link_collision'>
        <pose>0 0 0 0 -0 0</pose>
        <geometry>
          <mesh>
            <scale>1 1 1</scale>
            <uri>model://st_arm_description/meshes/stl/shoulder_pitch_link.STL</uri>
          </mesh>
        </geometry>
      </collision>
      -->
      <visual name='shoulder_pitch_link_visual'>
        <pose>0 0 0 0 -0 0</pose>
        <geometry>
          <mesh>
            <scale>1 1 1</scale>
            <uri>model://st_arm_description/meshes/stl/shoulder_pitch_link.STL</uri>
          </mesh>
        </geometry>
      </visual>
    </link>
    <joint name='elbow_pitch_joint' type='revolute'>
      <pose relative_to='shoulder_pitch_link'>0.25 0 0 0 -0 0</pose>
      <parent>shoulder_pitch_link</parent>
      <child>elbow_pitch_link</child>
      <axis>
        <xyz>0 1 0</xyz>
        <limit>
          <lower>-0.1</lower>
          <upper>2.8</upper>
          <effort>1</effort>
          <velocity>1</velocity>
        </limit>
        <dynamics>
          <damping>0.1</damping>
          <friction>0.1</friction>
          <spring_reference>0</spring_reference>
          <spring_stiffness>0</spring_stiffness>
        </dynamics>
      </axis>
    </joint>
    <link name='elbow_pitch_link'>
      <pose relative_to='elbow_pitch_joint'>0 0 0 0 -0 0</pose>
      <inertial>
        <pose>0.14489 0.001397 2.9e-05 0 -0 0</pose>
        <mass>0.15458</mass>
        <inertia>
          <ixx>2.7811e-05</ixx>
          <ixy>-7.6006e-08</ixy>
          <ixz>-2.7358e-10</ixz>
          <iyy>0.00024853</iyy>
          <iyz>-1.2741e-10</iyz>
          <izz>0.00024924</izz>
        </inertia>
      </inertial>
      <!--
      <collision name='elbow_pitch_link_collision'>
        <pose>0 0 0 0 -0 0</pose>
        <geometry>
          <mesh>
            <scale>1 1 1</scale>
            <uri>model://st_arm_description/meshes/stl/elbow_pitch_link.STL</uri>
          </mesh>
        </geometry>
      </collision>
      -->
      <visual name='elbow_pitch_link_visual'>
        <pose>0 0 0 0 -0 0</pose>
        <geometry>
          <mesh>
            <scale>1 1 1</scale>
            <uri>model://st_arm_description/meshes/stl/elbow_pitch_link.STL</uri>
          </mesh>
        </geometry>
      </visual>
    </link>
    <joint name='wrist_pitch_joint' type='revolute'>
      <pose relative_to='elbow_pitch_link'>0.25 0 0 0 -0 0</pose>
      <parent>elbow_pitch_link</parent>
      <child>wrist_pitch_link</child>
      <axis>
        <xyz>0 1 0</xyz>
        <limit>
          <lower>-2.8</lower>
          <upper>3.5</upper>
          <effort>1</effort>
          <velocity>1</velocity>
        </limit>
        <dynamics>
          <damping>0.1</damping>
          <friction>0.1</friction>
          <spring_reference>0</spring_reference>
          <spring_stiffness>0</spring_stiffness>
        </dynamics>
      </axis>
    </joint>
    <link name='wrist_pitch_link'>
      <pose relative_to='wrist_pitch_joint'>0 0 0 0 -0 0</pose>
      <inertial>
        <pose>0.045384 0 0.011625 0 -0 0</pose>
        <mass>0.04488</mass>
        <inertia>
          <ixx>1.056e-05</ixx>
          <ixy>9.3256e-17</ixy>
          <ixz>-1.6017e-09</ixz>
          <iyy>1.2042e-05</iyy>
          <iyz>5.2438e-15</iyz>
          <izz>7.0619e-06</izz>
        </inertia>
      </inertial>
      <!--
      <collision name='wrist_pitch_link_collision'>
        <pose>0 0 0 0 -0 0</pose>
        <geometry>
          <mesh>
            <scale>1 1 1</scale>
            <uri>model://st_arm_description/meshes/stl/wrist_pitch_link.STL</uri>
          </mesh>
        </geometry>
      </collision>
      -->
      <visual name='wrist_pitch_link_visual'>
        <pose>0 0 0 0 -0 0</pose>
        <geometry>
          <mesh>
            <scale>1 1 1</scale>
            <uri>model://st_arm_description/meshes/stl/wrist_pitch_link.STL</uri>
          </mesh>
        </geometry>
      </visual>
    </link>
    <joint name='wrist_roll_joint' type='revolute'>
      <pose relative_to='wrist_pitch_link'>0 0 0 0 -0 0</pose>
      <parent>wrist_pitch_link</parent>
      <child>wrist_roll_link</child>
      <axis>
        <xyz>1 0 0</xyz>
        <limit>
          <lower>-3.14</lower>
          <upper>3.14</upper>
          <effort>1</effort>
          <velocity>1</velocity>
        </limit>
        <dynamics>
          <damping>0.1</damping>
          <friction>0.1</friction>
          <spring_reference>0</spring_reference>
          <spring_stiffness>0</spring_stiffness>
        </dynamics>
      </axis>
    </joint>
    <link name='wrist_roll_link'>
      <pose relative_to='wrist_roll_joint'>0 0 0 0 -0 0</pose>
      <inertial>
        <pose>0.092875 0 0.000384 0 -0 0</pose>
        <mass>0.04488</mass>
        <inertia>
          <ixx>7.0619e-06</ixx>
          <ixy>-5.2437e-15</ixy>
          <ixz>1.6017e-09</ixz>
          <iyy>1.2042e-05</iyy>
          <iyz>9.3284e-17</iyz>
          <izz>1.056e-05</izz>
        </inertia>
      </inertial>
      <!--
      <collision name='wrist_roll_link_collision'>
        <pose>0 0 0 0 -0 0</pose>
        <geometry>
          <mesh>
            <scale>1 1 1</scale>
            <uri>model://st_arm_description/meshes/stl/wrist_roll_link.STL</uri>
          </mesh>
        </geometry>
      </collision>
      -->
      <visual name='wrist_roll_link_visual'>
        <pose>0 0 0 0 -0 0</pose>
        <geometry>
          <mesh>
            <scale>1 1 1</scale>
            <uri>model://st_arm_description/meshes/stl/wrist_roll_link.STL</uri>
          </mesh>
        </geometry>
      </visual>
    </link>
    <joint name='wrist_yaw_joint' type='revolute'>
      <pose relative_to='wrist_roll_link'>0.1045 0 0 0 -0 0</pose>
      <parent>wrist_roll_link</parent>
      <child>wrist_yaw_link</child>
      <axis>
        <xyz>0 0 1</xyz>
        <limit>
          <lower>-2</lower>
          <upper>2</upper>
          <effort>1</effort>
          <velocity>1</velocity>
        </limit>
        <dynamics>
          <damping>0.1</damping>
          <friction>0.1</friction>
          <spring_reference>0</spring_reference>
          <spring_stiffness>0</spring_stiffness>
        </dynamics>
      </axis>
    </joint>
    <link name='wrist_yaw_link'>
      <pose relative_to='wrist_yaw_joint'>0 0 0 0 -0 0</pose>
      <inertial>
        <pose>0.056543 0.00077 0.031224 0 -0 0</pose>
        <mass>0.0830727</mass>
        <inertia>
          <ixx>3.41437e-05</ixx>
          <ixy>4.57205e-08</ixy>
          <ixz>-1.45879e-08</ixz>
          <iyy>1.41539e-05</iyy>
          <iyz>-7.66183e-09</iyz>
          <izz>2.93287e-05</izz>
        </inertia>
      </inertial>
      <!--
      <collision name='wrist_yaw_link_collision'>
        <pose>0 0 0 0 -0 0</pose>
        <geometry>
          <mesh>
            <scale>1 1 1</scale>
            <uri>model://st_arm_description/meshes/stl/wrist_yaw_link.STL</uri>
          </mesh>
        </geometry>
      </collision>
      -->
      <visual name='wrist_yaw_link_visual'>
        <pose>0 0 0 0 -0 0</pose>
        <geometry>
          <mesh>
            <scale>1 1 1</scale>
            <uri>model://st_arm_description/meshes/stl/wrist_yaw_link.STL</uri>
          </mesh>
        </geometry>
      </visual>
    </link>
    <joint name='gripper_left_joint' type='prismatic'>
      <pose relative_to='wrist_yaw_link'>0.083595 0.00168 0 0 -0 0</pose>
      <parent>wrist_yaw_link</parent>
      <child>gripper_left_link</child>
      <axis>
        <xyz>0 -1 0</xyz>
        <limit>
          <lower>-0.05</lower>
          <upper>0</upper>
          <effort>1</effort>
          <velocity>1</velocity>
        </limit>
        <dynamics>
          <damping>0.1</damping>
          <friction>0.1</friction>
          <spring_reference>0</spring_reference>
          <spring_stiffness>0</spring_stiffness>
        </dynamics>
      </axis>
    </joint>
    <link name='gripper_left_link'>
      <pose relative_to='gripper_left_joint'>0 0 0 0 -0 0</pose>
      <inertial>
        <pose>0.011191 0.017208 -0 0 -0 0</pose>
        <mass>0.0151655</mass>
        <inertia>
          <ixx>1.52745e-06</ixx>
          <ixy>1.20106e-06</ixy>
          <ixz>3.87211e-18</ixz>
          <iyy>7.43136e-06</iyy>
          <iyz>-6.58552e-19</iyz>
          <izz>8.50839e-06</izz>
        </inertia>
      </inertial>
      <collision name='gripper_left_link_collision'>
        <pose>0 0 0 0 -0 0</pose>
        <geometry>
          <mesh>
            <scale>1 1 1</scale>
            <uri>model://st_arm_description/meshes/stl/gripper_left_link.STL</uri>
          </mesh>
        </geometry>
      </collision>
      <visual name='gripper_left_link_visual'>
        <pose>0 0 0 0 -0 0</pose>
        <geometry>
          <mesh>
            <scale>1 1 1</scale>
            <uri>model://st_arm_description/meshes/stl/gripper_left_link.STL</uri>
          </mesh>
        </geometry>
      </visual>
    </link>
    <joint name='gripper_right_joint' type='prismatic'>
      <pose relative_to='wrist_yaw_link'>0.083595 0.00168 0 0 -0 0</pose>
      <parent>wrist_yaw_link</parent>
      <child>gripper_right_link</child>
      <axis>
        <xyz>0 1 0</xyz>
        <limit>
          <lower>-0.05</lower>
          <upper>0</upper>
          <effort>1</effort>
          <velocity>1</velocity>
        </limit>
        <dynamics>
          <damping>0.1</damping>
          <friction>0.1</friction>
          <spring_reference>0</spring_reference>
          <spring_stiffness>0</spring_stiffness>
        </dynamics>
      </axis>
    </joint>
    <link name='gripper_right_link'>
      <pose relative_to='gripper_right_joint'>0 0 0 0 -0 0</pose>
      <inertial>
        <pose>0.011191 -0.017208 0 0 -0 0</pose>
        <mass>0.0151655</mass>
        <inertia>
          <ixx>1.52745e-06</ixx>
          <ixy>-1.20106e-06</ixy>
          <ixz>1.01095e-20</ixz>
          <iyy>7.43136e-06</iyy>
          <iyz>9.01849e-21</iyz>
          <izz>8.50839e-06</izz>
        </inertia>
      </inertial>
      <collision name='gripper_right_link_collision'>
        <pose>0 0 0 0 -0 0</pose>
        <geometry>
          <mesh>
            <scale>1 1 1</scale>
            <uri>model://st_arm_description/meshes/stl/gripper_right_link.STL</uri>
          </mesh>
        </geometry>
      </collision>
      <visual name='gripper_right_link_visual'>
        <pose>0 0 0 0 -0 0</pose>
        <geometry>
          <mesh>
            <scale>1 1 1</scale>
            <uri>model://st_arm_description/meshes/stl/gripper_right_link.STL</uri>
          </mesh>
        </geometry>
      </visual>
    </link>
  </model>
</sdf>
